I am using python3.11

Installed : ultralytics==8.3.32  The latest verion is infected with cryptominer virus

pip install ultralytics==8.3.32

2) The content of C:\Users\hi\AppData\Roaming\Ultralytics\settings.json:
   
 {
  "settings_version": "0.0.6",
  "datasets_dir": "C:\\Users\\hi\\Desktop\\projects\\python_projects\\ai_projects\\computer_vision",
  "weights_dir": "weights",
  "runs_dir": "runs",
  "uuid": "0997c02de2dc08c8a6784b88138957d8572ab2eebcdb0ca32e44f8d610d67f5d",
  "sync": true,
  "api_key": "",
  "openai_api_key": "",
  "clearml": true,
  "comet": true,
  "dvc": true,
  "hub": true,
  "mlflow": true,
  "neptune": true,
  "raytune": true,
  "tensorboard": true,
  "wandb": true,
  "vscode_msg": true
}

*) I downloaded the zip file of dataset : coco8-pose